Workbook
Name Applied: 'Helper(IMPORTANT!)'!$D$4:$D$11
Name Core: 'Helper(IMPORTANT!)'!$C$4:$C$22
Name ngoyab: FRONT!$A$6:$BO$20
Name Other_Subjects: 'Helper(IMPORTANT!)'!$F$4:$F$6
Name Specialized: 'Helper(IMPORTANT!)'!$E$4:$E$12

Sheet FRONT
P1: REPUBLIC OF THE PHILIPPINES | BH1: SF10-SHS
P2: DEPARTMENT OF EDUCATION
P3: SENIOR HIGH SCHOOL STUDENT PERMANENT RECORD
A6: LEARNER'S INFORMATION
A8: LAST NAME: | T8: FIRST NAME: | AS8: MIDDLE NAME:
A9: LRN: | R9: Date of Birth (MM/DD/YYYY): | AL9: Sex: | AS9: Date of SHS Admission (MM/DD/YYYY):
A11: ELIGIBILITY FOR SHS ENROLMENT
B13: High School Completer* | K13: Gen. Ave: | S13: ⁄ | T13: Junior High School Completer | AD13: Gen. Ave:
A14: Date of Graduation/Completion (MM/DD/YYYY): | P14: 43924 | U14: Name of School: | Z14: PANTAO NATIONAL HIGH SCHOOL | AQ14: School Address: | AW14: PANTAO, LIBON, ALBAY
B16: PEPT Passer** | H16: Rating: | T16: ALS A&E Passer*** | Z16: Rating: | AI16: Others (Pls. Specify):
A17: Date of Examination/Assessment (MM/DD/YYYY): | W17: Name and Address of Community Learning Center:
A18: *High School Completers are students who graduated from secondary school under the old curriculum | AG18: ***ALS A&E - Alternative Learning System Accreditation and Equivalency Test for JHS
A19: **PEPT - Philippine Educational Placement Test for JHS | BG19: depedtambayan
A21: SCHOLASTIC RECORD
A23: SCHOOL: | E23: PANTAO NATIONAL HIGH SCHOOL | AB23: SCHOOL ID: | AF23: 301860 | AM23: GRADE LEVEL: | AS23: 11 | AY23: SY: | BA23: 2020-2021 | BH23: SEM: | BK23: 1ST
A25: TRACK/STRAND: | G25: ACADEMIC TRACK/ ACCOUNTANCY, BUSINESS AND MANAGEMENT STRAND | AN25: SECTION: | AS25: MODESTY
A27: Indicate if Subject is CORE, APPLIED, or SPECIALIZED | I27: SUBJECTS | AT27: Quarter | BD27: SEM FINAL GRADE | BI27: ACTION TAKEN
AT29: =IF(BK23="","",IF(BK23="1ST","1ST",IF(BK23="2ND","3RD"))) -> 1ST | AY29: =IF(BK23="","",IF(BK23="1ST","2ND",IF(BK23="2ND","4TH"))) -> 2ND
A31: Core | I31: Oral Communication | BD31: =IF(OR(AT31="",AY31=""),"",IF(ISERROR(ROUND(AVERAGE(AT31,AY31),0)),"",ROUND(AVERAGE(AT31,AY31),0))) | BI31: =IF(OR(AT31="",AY31="",BD31=""),"",IF(BD31>=75,"PASSED","FAILED"))
A32: Core | I32: Komunikasyon at Pananaliksik sa Wika at Kulturang Pilipino | BD32: =IF(OR(AT32="",AY32=""),"",IF(ISERROR(ROUND(AVERAGE(AT32,AY32),0)),"",ROUND(AVERAGE(AT32,AY32),0))) | BI32: =IF(OR(AT32="",AY32="",BD32=""),"",IF(BD32>=75,"PASSED","FAILED"))
A33: Core | I33: Media and Information Literacy | BD33: =IF(OR(AT33="",AY33=""),"",IF(ISERROR(ROUND(AVERAGE(AT33,AY33),0)),"",ROUND(AVERAGE(AT33,AY33),0))) | BI33: =IF(OR(AT33="",AY33="",BD33=""),"",IF(BD33>=75,"PASSED","FAILED"))
A34: Core | I34: General Mathematics | BD34: =IF(OR(AT34="",AY34=""),"",IF(ISERROR(ROUND(AVERAGE(AT34,AY34),0)),"",ROUND(AVERAGE(AT34,AY34),0))) | BI34: =IF(OR(AT34="",AY34="",BD34=""),"",IF(BD34>=75,"PASSED","FAILED"))
A35: Core | I35: Earth Science | BD35: =IF(OR(AT35="",AY35=""),"",IF(ISERROR(ROUND(AVERAGE(AT35,AY35),0)),"",ROUND(AVERAGE(AT35,AY35),0))) | BI35: =IF(OR(AT35="",AY35="",BD35=""),"",IF(BD35>=75,"PASSED","FAILED"))
A36: Core | I36: Personal Development/Pansariling Kaunlaran | BD36: =IF(OR(AT36="",AY36=""),"",IF(ISERROR(ROUND(AVERAGE(AT36,AY36),0)),"",ROUND(AVERAGE(AT36,AY36),0))) | BI36: =IF(OR(AT36="",AY36="",BD36=""),"",IF(BD36>=75,"PASSED","FAILED"))
A37: Core | I37: Understanding Culture, Society and Politics | BD37: =IF(OR(AT37="",AY37=""),"",IF(ISERROR(ROUND(AVERAGE(AT37,AY37),0)),"",ROUND(AVERAGE(AT37,AY37),0))) | BI37: =IF(OR(AT37="",AY37="",BD37=""),"",IF(BD37>=75,"PASSED","FAILED"))
A38: Core | I38: Physical Education and Health | BD38: =IF(OR(AT38="",AY38=""),"",IF(ISERROR(ROUND(AVERAGE(AT38,AY38),0)),"",ROUND(AVERAGE(AT38,AY38),0))) | BI38: =IF(OR(AT38="",AY38="",BD38=""),"",IF(BD38>=75,"PASSED","FAILED"))
A39: Specialized | I39: Organization and Management | BD39: =IF(OR(AT39="",AY39=""),"",IF(ISERROR(ROUND(AVERAGE(AT39,AY39),0)),"",ROUND(AVERAGE(AT39,AY39),0))) | BI39: =IF(OR(AT39="",AY39="",BD39=""),"",IF(BD39>=75,"PASSED","FAILED"))
A40: Other_Subjects | I40: Homeroom Guidance | BD40: =IF(OR(AT40="",AY40=""),"",IF(ISERROR(ROUND(AVERAGE(AT40,AY40),0)),"",ROUND(AVERAGE(AT40,AY40),0))) | BI40: =IF(OR(AT40="",AY40="",BD40=""),"",IF(BD40>=75,"PASSED","FAILED"))
BD41: =IF(OR(AT41="",AY41=""),"",IF(ISERROR(ROUND(AVERAGE(AT41,AY41),0)),"",ROUND(AVERAGE(AT41,AY41),0))) | BI41: =IF(OR(AT41="",AY41="",BD41=""),"",IF(BD41>=75,"PASSED","FAILED"))
BD42: =IF(OR(AT42="",AY42=""),"",IF(ISERROR(ROUND(AVERAGE(AT42,AY42),0)),"",ROUND(AVERAGE(AT42,AY42),0))) | BI42: =IF(OR(AT42="",AY42="",BD42=""),"",IF(BD42>=75,"PASSED","FAILED"))
A43: General Ave. for the Semester: | BD43: =IFERROR(ROUND((SUM(BD31:BD42,BD58:BD61)-SUM(AT58:AT61))/(COUNTA(BD31:BD42)-COUNTBLANK(BD31:BD42)),0),"") | BI43: =IF(BD43="","",IF(BD43>=75,"PASSED","FAILED"))
A45: REMARKS: | E45: PROMOTED
A47: Prepared by: | V47: Certified True and Correct: | AZ47: Date Checked (MM/DD/YYYY):
A49: BENEDICTA B. AQUILER | Y49: MARILOU A. SEDON, GC-1 | AZ49: 44238
A50: Signature of Adviser over Printed Name | Y50: Signature of Authorized Person over Printed Name, Designation
A52: REMEDIAL CLASSES | I52: Conducted from (MM/DD/YYYY): | W52: to (MM/DD/YYYY): | AH52: SCHOOL: | BF52: SCHOOL ID:
A54: Indicate if Subject is CORE, APPLIED, or SPECIALIZED | I54: SUBJECTS | AT54: SEM FINAL GRADE | AY54: REMEDIAL CLASS MARK | BD54: RECOMPUTED FINAL GRADE | BI54: ACTION TAKEN
BD58: =IF(OR(AT58="",AY58=""),"",IF(ISERROR(ROUND(AVERAGE(AT58,AY58),0)),"",ROUND(AVERAGE(AT58,AY58),0))) | BI58: =IF(OR(AT58="",AY58="",BD58=""),"",IF(BD58>=75,"PASSED","FAILED"))
BD59: =IF(OR(AT59="",AY59=""),"",IF(ISERROR(ROUND(AVERAGE(AT59,AY59),0)),"",ROUND(AVERAGE(AT59,AY59),0))) | BI59: =IF(OR(AT59="",AY59="",BD59=""),"",IF(BD59>=75,"PASSED","FAILED"))
BD60: =IF(OR(AT60="",AY60=""),"",IF(ISERROR(ROUND(AVERAGE(AT60,AY60),0)),"",ROUND(AVERAGE(AT60,AY60),0))) | BI60: =IF(OR(AT60="",AY60="",BD60=""),"",IF(BD60>=75,"PASSED","FAILED"))
...

Sheet BACK
A1: Page 2 | I1: =IF(FRONT!F8="","",FRONT!F8&","&" "&FRONT!Y8&" "&FRONT!AZ8) | BH1: SF10-SHS
A4: SCHOOL: | AB4: SCHOOL ID: | AM4: GRADE LEVEL: | AY4: SY: | BH4: SEM:
A5: TRACK/STRAND: | AN5: SECTION:
A7: Indicate if Subject is CORE, APPLIED, or SPECIALIZED | I7: SUBJECTS | AT7: Quarter | BD7: SEM FINAL GRADE | BI7: ACTION TAKEN
AT9: =IF(BK4="","",IF(BK4="1ST","1ST",IF(BK4="2ND","3RD"))) | AY9: =IF(BK4="","",IF(BK4="1ST","2ND",IF(BK4="2ND","4TH")))
BD11: =IF(OR(AT11="",AY11=""),"",IF(ISERROR(ROUND(AVERAGE(AT11,AY11),0)),"",ROUND(AVERAGE(AT11,AY11),0))) | BI11: =IF(OR(AT11="",AY11="",BD11=""),"",IF(BD11>=75,"PASSED","FAILED"))
BD12: =IF(OR(AT12="",AY12=""),"",IF(ISERROR(ROUND(AVERAGE(AT12,AY12),0)),"",ROUND(AVERAGE(AT12,AY12),0))) | BI12: =IF(OR(AT12="",AY12="",BD12=""),"",IF(BD12>=75,"PASSED","FAILED"))
BD13: =IF(OR(AT13="",AY13=""),"",IF(ISERROR(ROUND(AVERAGE(AT13,AY13),0)),"",ROUND(AVERAGE(AT13,AY13),0))) | BI13: =IF(OR(AT13="",AY13="",BD13=""),"",IF(BD13>=75,"PASSED","FAILED"))
BD14: =IF(OR(AT14="",AY14=""),"",IF(ISERROR(ROUND(AVERAGE(AT14,AY14),0)),"",ROUND(AVERAGE(AT14,AY14),0))) | BI14: =IF(OR(AT14="",AY14="",BD14=""),"",IF(BD14>=75,"PASSED","FAILED"))
BD15: =IF(OR(AT15="",AY15=""),"",IF(ISERROR(ROUND(AVERAGE(AT15,AY15),0)),"",ROUND(AVERAGE(AT15,AY15),0))) | BI15: =IF(OR(AT15="",AY15="",BD15=""),"",IF(BD15>=75,"PASSED","FAILED"))
BD16: =IF(OR(AT16="",AY16=""),"",IF(ISERROR(ROUND(AVERAGE(AT16,AY16),0)),"",ROUND(AVERAGE(AT16,AY16),0))) | BI16: =IF(OR(AT16="",AY16="",BD16=""),"",IF(BD16>=75,"PASSED","FAILED"))
BD17: =IF(OR(AT17="",AY17=""),"",IF(ISERROR(ROUND(AVERAGE(AT17,AY17),0)),"",ROUND(AVERAGE(AT17,AY17),0))) | BI17: =IF(OR(AT17="",AY17="",BD17=""),"",IF(BD17>=75,"PASSED","FAILED"))
BD18: =IF(OR(AT18="",AY18=""),"",IF(ISERROR(ROUND(AVERAGE(AT18,AY18),0)),"",ROUND(AVERAGE(AT18,AY18),0))) | BI18: =IF(OR(AT18="",AY18="",BD18=""),"",IF(BD18>=75,"PASSED","FAILED"))
BD19: =IF(OR(AT19="",AY19=""),"",IF(ISERROR(ROUND(AVERAGE(AT19,AY19),0)),"",ROUND(AVERAGE(AT19,AY19),0))) | BI19: =IF(OR(AT19="",AY19="",BD19=""),"",IF(BD19>=75,"PASSED","FAILED"))
BD20: =IF(OR(AT20="",AY20=""),"",IF(ISERROR(ROUND(AVERAGE(AT20,AY20),0)),"",ROUND(AVERAGE(AT20,AY20),0))) | BI20: =IF(OR(AT20="",AY20="",BD20=""),"",IF(BD20>=75,"PASSED","FAILED"))
BD21: =IF(OR(AT21="",AY21=""),"",IF(ISERROR(ROUND(AVERAGE(AT21,AY21),0)),"",ROUND(AVERAGE(AT21,AY21),0))) | BI21: =IF(OR(AT21="",AY21="",BD21=""),"",IF(BD21>=75,"PASSED","FAILED"))
BD22: =IF(OR(AT22="",AY22=""),"",IF(ISERROR(ROUND(AVERAGE(AT22,AY22),0)),"",ROUND(AVERAGE(AT22,AY22),0))) | BI22: =IF(OR(AT22="",AY22="",BD22=""),"",IF(BD22>=75,"PASSED","FAILED"))
A23: General Ave. for the Semester: | BD23: =IFERROR(ROUND((SUM(BD11:BD22,BD38:BD41)-SUM(AT38:AT41))/(COUNTA(BD11:BD22)-COUNTBLANK(BD11:BD22)),0),"") | BI23: =IF(BD23="","",IF(BD23>=75,"PASSED","FAILED"))
A25: REMARKS:
A27: Prepared by: | V27: Certified True and Correct: | AZ27: Date Checked (MM/DD/YYYY):
A30: Signature of Adviser over Printed Name | Y30: Signature of Authorized Person over Printed Name, Designation
A32: REMEDIAL CLASSES | G32: Conducted from (MM/DD/YYYY): | W32: to (MM/DD/YYYY): | AH32: SCHOOL: | BF32: SCHOOL ID:
A34: Indicate if Subject is CORE, APPLIED, or SPECIALIZED | I34: SUBJECTS | AT34: SEM FINAL GRADE | AY34: REMEDIAL CLASS MARK | BD34: RECOMPUTED FINAL GRADE | BI34: ACTION TAKEN
BD38: =IF(OR(AT38="",AY38=""),"",IF(ISERROR(ROUND(AVERAGE(AT38,AY38),0)),"",ROUND(AVERAGE(AT38,AY38),0))) | BI38: =IF(OR(AT38="",AY38="",BD38=""),"",IF(BD38>=75,"PASSED","FAILED"))
BD39: =IF(OR(AT39="",AY39=""),"",IF(ISERROR(ROUND(AVERAGE(AT39,AY39),0)),"",ROUND(AVERAGE(AT39,AY39),0))) | BI39: =IF(OR(AT39="",AY39="",BD39=""),"",IF(BD39>=75,"PASSED","FAILED"))
BD40: =IF(OR(AT40="",AY40=""),"",IF(ISERROR(ROUND(AVERAGE(AT40,AY40),0)),"",ROUND(AVERAGE(AT40,AY40),0))) | BI40: =IF(OR(AT40="",AY40="",BD40=""),"",IF(BD40>=75,"PASSED","FAILED"))
BD41: =IF(OR(AT41="",AY41=""),"",IF(ISERROR(ROUND(AVERAGE(AT41,AY41),0)),"",ROUND(AVERAGE(AT41,AY41),0))) | BI41: =IF(OR(AT41="",AY41="",BD41=""),"",IF(BD41>=75,"PASSED","FAILED"))
A43: Name of Teacher/Adviser: | AT43: Signature:
A46: SCHOOL: | AB46: SCHOOL ID: | AM46: GRADE LEVEL: | AY46: SY: | BH46: SEM:
A48: TRACK/STRAND: | AN48: SECTION:
A50: Indicate if Subject is CORE, APPLIED, or SPECIALIZED | I50: SUBJECTS | AT50: Quarter | BD50: SEM FINAL GRADE | BI50: ACTION TAKEN
AT52: =IF(BK46="","",IF(BK46="1ST","1ST",IF(BK46="2ND","3RD"))) | AY52: =IF(BK46="","",IF(BK46="1ST","2ND",IF(BK46="2ND","4TH")))
BD54: =IF(OR(AT54="",AY54=""),"",IF(ISERROR(ROUND(AVERAGE(AT54,AY54),0)),"",ROUND(AVERAGE(AT54,AY54),0))) | BI54: =IF(OR(AT54="",AY54="",BD54=""),"",IF(BD54>=75,"PASSED","FAILED"))
BD55: =IF(OR(AT55="",AY55=""),"",IF(ISERROR(ROUND(AVERAGE(AT55,AY55),0)),"",ROUND(AVERAGE(AT55,AY55),0))) | BI55: =IF(OR(AT55="",AY55="",BD55=""),"",IF(BD55>=75,"PASSED","FAILED"))
BD56: =IF(OR(AT56="",AY56=""),"",IF(ISERROR(ROUND(AVERAGE(AT56,AY56),0)),"",ROUND(AVERAGE(AT56,AY56),0))) | BI56: =IF(OR(AT56="",AY56="",BD56=""),"",IF(BD56>=75,"PASSED","FAILED"))
BD57: =IF(OR(AT57="",AY57=""),"",IF(ISERROR(ROUND(AVERAGE(AT57,AY57),0)),"",ROUND(AVERAGE(AT57,AY57),0))) | BI57: =IF(OR(AT57="",AY57="",BD57=""),"",IF(BD57>=75,"PASSED","FAILED"))
BD58: =IF(OR(AT58="",AY58=""),"",IF(ISERROR(ROUND(AVERAGE(AT58,AY58),0)),"",ROUND(AVERAGE(AT58,AY58),0))) | BI58: =IF(OR(AT58="",AY58="",BD58=""),"",IF(BD58>=75,"PASSED","FAILED"))
BD59: =IF(OR(AT59="",AY59=""),"",IF(ISERROR(ROUND(AVERAGE(AT59,AY59),0)),"",ROUND(AVERAGE(AT59,AY59),0))) | BI59: =IF(OR(AT59="",AY59="",BD59=""),"",IF(BD59>=75,"PASSED","FAILED"))
BD60: =IF(OR(AT60="",AY60=""),"",IF(ISERROR(ROUND(AVERAGE(AT60,AY60),0)),"",ROUND(AVERAGE(AT60,AY60),0))) | BI60: =IF(OR(AT60="",AY60="",BD60=""),"",IF(BD60>=75,"PASSED","FAILED"))
BD61: =IF(OR(AT61="",AY61=""),"",IF(ISERROR(ROUND(AVERAGE(AT61,AY61),0)),"",ROUND(AVERAGE(AT61,AY61),0))) | BI61: =IF(OR(AT61="",AY61="",BD61=""),"",IF(BD61>=75,"PASSED","FAILED"))
...

Sheet ANNEX
A1: =IF(FRONT!F8="","",FRONT!F8&","&" "&FRONT!Y8&" "&FRONT!AZ8) | I1: SF10-SHS
A3: ANNEX: LIST OF SUBJECTS TAKEN
A4: Please check the subjects passed by the student
A6: CORE SUBJECTS
A7: {=IFERROR(INDEX('Helper(IMPORTANT!)'!$J$7:$L$86,MATCH(1,('Helper(IMPORTANT!)'!$J$7:$J$86=C7)*('Helper(IMPORTANT!)'!$K$7:$K$86='Helper(IMPORTANT!)'!$J$6),0),3),"")} | C7: Oral Communication
A8: {=IFERROR(INDEX('Helper(IMPORTANT!)'!$J$7:$L$86,MATCH(1,('Helper(IMPORTANT!)'!$J$7:$J$86=C8)*('Helper(IMPORTANT!)'!$K$7:$K$86='Helper(IMPORTANT!)'!$J$6),0),3),"")} | C8: Reading and Writing
A9: {=IFERROR(INDEX('Helper(IMPORTANT!)'!$J$7:$L$86,MATCH(1,('Helper(IMPORTANT!)'!$J$7:$J$86=C9)*('Helper(IMPORTANT!)'!$K$7:$K$86='Helper(IMPORTANT!)'!$J$6),0),3),"")} | C9: Komunikasyon at Pananaliksik sa Wika at Kulturang Pilipino
A10: {=IFERROR(INDEX('Helper(IMPORTANT!)'!$J$7:$L$86,MATCH(1,('Helper(IMPORTANT!)'!$J$7:$J$86=C10)*('Helper(IMPORTANT!)'!$K$7:$K$86='Helper(IMPORTANT!)'!$J$6),0),3),"")} | C10: Pagbasa at Pagsusuri ng Iba't Ibang Teksto Tungo sa Pananaliksik
A11: {=IFERROR(INDEX('Helper(IMPORTANT!)'!$J$7:$L$86,MATCH(1,('Helper(IMPORTANT!)'!$J$7:$J$86=C11)*('Helper(IMPORTANT!)'!$K$7:$K$86='Helper(IMPORTANT!)'!$J$6),0),3),"")} | C11: 21st Century Literature from the Philippines and the World
A12: {=IFERROR(INDEX('Helper(IMPORTANT!)'!$J$7:$L$86,MATCH(1,('Helper(IMPORTANT!)'!$J$7:$J$86=C12)*('Helper(IMPORTANT!)'!$K$7:$K$86='Helper(IMPORTANT!)'!$J$6),0),3),"")} | C12: Contemporary Philippine Arts from the Regions
A13: {=IFERROR(INDEX('Helper(IMPORTANT!)'!$J$7:$L$86,MATCH(1,('Helper(IMPORTANT!)'!$J$7:$J$86=C13)*('Helper(IMPORTANT!)'!$K$7:$K$86='Helper(IMPORTANT!)'!$J$6),0),3),"")} | C13: Media and Information Literacy
A14: {=IFERROR(INDEX('Helper(IMPORTANT!)'!$J$7:$L$86,MATCH(1,('Helper(IMPORTANT!)'!$J$7:$J$86=C14)*('Helper(IMPORTANT!)'!$K$7:$K$86='Helper(IMPORTANT!)'!$J$6),0),3),"")} | C14: General Mathematics
A15: {=IFERROR(INDEX('Helper(IMPORTANT!)'!$J$7:$L$86,MATCH(1,('Helper(IMPORTANT!)'!$J$7:$J$86=C15)*('Helper(IMPORTANT!)'!$K$7:$K$86='Helper(IMPORTANT!)'!$J$6),0),3),"")} | C15: Statistics and Probability
A16: {=IFERROR(INDEX('Helper(IMPORTANT!)'!$J$7:$L$86,MATCH(1,('Helper(IMPORTANT!)'!$J$7:$J$86=C16)*('Helper(IMPORTANT!)'!$K$7:$K$86='Helper(IMPORTANT!)'!$J$6),0),3),"")} | C16: Earth and Life Science*
A17: {=IFERROR(INDEX('Helper(IMPORTANT!)'!$J$7:$L$86,MATCH(1,('Helper(IMPORTANT!)'!$J$7:$J$86=C17)*('Helper(IMPORTANT!)'!$K$7:$K$86='Helper(IMPORTANT!)'!$J$6),0),3),"")} | C17: Physical Science*
A18: {=IFERROR(INDEX('Helper(IMPORTANT!)'!$J$7:$L$86,MATCH(1,('Helper(IMPORTANT!)'!$J$7:$J$86=C18)*('Helper(IMPORTANT!)'!$K$7:$K$86='Helper(IMPORTANT!)'!$J$6),0),3),"")} | C18: Personal Development/Pansariling Kaunlaran
... A20: {=IFERROR(INDEX('Helper(IMPORTANT!)'!$J$7:$L$86,MATCH(1,('Helper(IMPORTANT!)'!$J$7:$J$86=C20)*('Helper(IMPORTANT!)'!$K$7:$K$86='Helper(IMPORTANT!)'!$J$6),0),3),"")} | C20: Introduction to the Philosophy of the Human Person/Pambungad sa Pilosopiya ng Tao
A21: =IF(COUNTIF('Helper(IMPORTANT!)'!M7:M14,"PASSED")>=4,"∕","") | C21: Physical Education and Health (spread out in 4 semesters)
A22: *STEM students will take these instead:
A23: {=IFERROR(INDEX('Helper(IMPORTANT!)'!$J$7:$L$86,MATCH(1,('Helper(IMPORTANT!)'!$J$7:$J$86=C23)*('Helper(IMPORTANT!)'!$K$7:$K$86='Helper(IMPORTANT!)'!$J$6),0),3),"")} | C23: Earth Science
A24: {=IFERROR(INDEX('Helper(IMPORTANT!)'!$J$7:$L$86,MATCH(1,('Helper(IMPORTANT!)'!$J$7:$J$86=C24)*('Helper(IMPORTANT!)'!$K$7:$K$86='Helper(IMPORTANT!)'!$J$6),0),3),"")} | C24: Disaster Readiness and Risk Reduction
A25: Subject substitutions, if any:
A26: {=IFERROR(INDEX('Helper(IMPORTANT!)'!$J$7:$L$86,MATCH(1,('Helper(IMPORTANT!)'!$J$7:$J$86=C26)*('Helper(IMPORTANT!)'!$K$7:$K$86='Helper(IMPORTANT!)'!$J$6),0),3),"")}
A27: {=IFERROR(INDEX('Helper(IMPORTANT!)'!$J$7:$L$86,MATCH(1,('Helper(IMPORTANT!)'!$J$7:$J$86=C27)*('Helper(IMPORTANT!)'!$K$7:$K$86='Helper(IMPORTANT!)'!$J$6),0),3),"")}
A29: APPLIED SUBJECTS
A30: {=IFERROR(INDEX('Helper(IMPORTANT!)'!$J$7:$L$86,MATCH(1,('Helper(IMPORTANT!)'!$J$7:$J$86=C30)*('Helper(IMPORTANT!)'!$K$7:$K$86='Helper(IMPORTANT!)'!$J$6),0),3),"")} | C30: English for Academic and Professional Purposes
A31: {=IFERROR(INDEX('Helper(IMPORTANT!)'!$J$7:$L$86,MATCH(1,('Helper(IMPORTANT!)'!$J$7:$J$86=C31)*('Helper(IMPORTANT!)'!$K$7:$K$86='Helper(IMPORTANT!)'!$J$6),0),3),"")} | C31: Practical Research 1
A32: {=IFERROR(INDEX('Helper(IMPORTANT!)'!$J$7:$L$86,MATCH(1,('Helper(IMPORTANT!)'!$J$7:$J$86=C32)*('Helper(IMPORTANT!)'!$K$7:$K$86='Helper(IMPORTANT!)'!$J$6),0),3),"")} | C32: Practical Research 2
A33: {=IFERROR(INDEX('Helper(IMPORTANT!)'!$J$7:$L$86,MATCH(1,('Helper(IMPORTANT!)'!$J$7:$J$86=C33)*('Helper(IMPORTANT!)'!$K$7:$K$86='Helper(IMPORTANT!)'!$J$6),0),3),"")} | C33: Filipino sa Piling Larang
A34: {=IFERROR(INDEX('Helper(IMPORTANT!)'!$J$7:$L$86,MATCH(1,('Helper(IMPORTANT!)'!$J$7:$J$86=C34)*('Helper(IMPORTANT!)'!$K$7:$K$86='Helper(IMPORTANT!)'!$J$6),0),3),"")} | C34: Empowerment Technologies
A35: {=IFERROR(INDEX('Helper(IMPORTANT!)'!$J$7:$L$86,MATCH(1,('Helper(IMPORTANT!)'!$J$7:$J$86=C35)*('Helper(IMPORTANT!)'!$K$7:$K$86='Helper(IMPORTANT!)'!$J$6),0),3),"")} | C35: Entrepreneurship
A36: {=IFERROR(INDEX('Helper(IMPORTANT!)'!$J$7:$L$86,MATCH(1,('Helper(IMPORTANT!)'!$J$7:$J$86=C36)*('Helper(IMPORTANT!)'!$K$7:$K$86='Helper(IMPORTANT!)'!$J$6),0),3),"")} | C36: Inquiries, Investigations and Immersion
A38: SPECIALIZED SUBJECTS (Please write the list of subjects below)
A39: {=IFERROR(INDEX('Helper(IMPORTANT!)'!$J$7:$L$86,MATCH(1,('Helper(IMPORTANT!)'!$J$7:$J$86=C39)*('Helper(IMPORTANT!)'!$K$7:$K$86='Helper(IMPORTANT!)'!$J$6),0),3),"")} | C39: Organization and Management
A40: {=IFERROR(INDEX('Helper(IMPORTANT!)'!$J$7:$L$86,MATCH(1,('Helper(IMPORTANT!)'!$J$7:$J$86=C40)*('Helper(IMPORTANT!)'!$K$7:$K$86='Helper(IMPORTANT!)'!$J$6),0),3),"")} | C40: Trend, Networks, and Critical Thinking in the 21st Century
A41: {=IFERROR(INDEX('Helper(IMPORTANT!)'!$J$7:$L$86,MATCH(1,('Helper(IMPORTANT!)'!$J$7:$J$86=C41)*('Helper(IMPORTANT!)'!$K$7:$K$86='Helper(IMPORTANT!)'!$J$6),0),3),"")} | C41: Food and Beverage Services NC II
A42: {=IFERROR(INDEX('Helper(IMPORTANT!)'!$J$7:$L$86,MATCH(1,('Helper(IMPORTANT!)'!$J$7:$J$86=C42)*('Helper(IMPORTANT!)'!$K$7:$K$86='Helper(IMPORTANT!)'!$J$6),0),3),"")}
A43: {=IFERROR(INDEX('Helper(IMPORTANT!)'!$J$7:$L$86,MATCH(1,('Helper(IMPORTANT!)'!$J$7:$J$86=C43)*('Helper(IMPORTANT!)'!$K$7:$K$86='Helper(IMPORTANT!)'!$J$6),0),3),"")}
A44: {=IFERROR(INDEX('Helper(IMPORTANT!)'!$J$7:$L$86,MATCH(1,('Helper(IMPORTANT!)'!$J$7:$J$86=C44)*('Helper(IMPORTANT!)'!$K$7:$K$86='Helper(IMPORTANT!)'!$J$6),0),3),"")}
A45: {=IFERROR(INDEX('Helper(IMPORTANT!)'!$J$7:$L$86,MATCH(1,('Helper(IMPORTANT!)'!$J$7:$J$86=C45)*('Helper(IMPORTANT!)'!$K$7:$K$86='Helper(IMPORTANT!)'!$J$6),0),3),"")}
...

Sheet Helper(IMPORTANT!)
B1: Helper Columns
B2: yongbarba@gmail.com
B3: Subjects | C3: Core | D3: Applied | E3: Specialized | F3: Other Subjects
A4: 1 | B4: =IF(FRONT!A31="Core","Core",IF(FRONT!A31="Applied","Applied",IF(FRONT!A31="Specialized","Specialized",IF(FRONT!A31="Other_Subjects","Other_Subjects")))) -> Core | C4: 21st Century Literature from the Philippines and the World | D4: Empowerment Technologies | E4: =IF(ANNEX!C39="","",ANNEX!C39) -> Organization and Management | F4: =IF(ANNEX!C50="","",ANNEX!C50) -> Homeroom Guidance
B5: =IF(FRONT!A32="Core","Core",IF(FRONT!A32="Applied","Applied",IF(FRONT!A32="Specialized","Specialized",IF(FRONT!A32="Other_Subjects","Other_Subjects")))) -> Core | C5: Contemporary Philippine Arts from the Regions | D5: English for Academic and Professional Purposes | E5: =IF(ANNEX!C40="","",ANNEX!C40) -> Trend, Networks, and Critical Thinking in the 21st Century | F5: =IF(ANNEX!C51="","",ANNEX!C51)
B6: =IF(FRONT!A33="Core","Core",IF(FRONT!A33="Applied","Applied",IF(FRONT!A33="Specialized","Specialized",IF(FRONT!A33="Other_Subjects","Other_Subjects")))) -> Core | C6: Disaster Readiness and Risk Reduction | D6: Entrepreneurship | E6: =IF(ANNEX!C41="","",ANNEX!C41) -> Food and Beverage Services NC II | F6: =IF(ANNEX!C52="","",ANNEX!C52) | J6: PASSED | M6: Physical Education and Health
B7: =IF(FRONT!A34="Core","Core",IF(FRONT!A34="Applied","Applied",IF(FRONT!A34="Specialized","Specialized",IF(FRONT!A34="Other_Subjects","Other_Subjects")))) -> Core | C7: Earth and Life Science* | D7: Filipino sa Piling Larang | E7: =IF(ANNEX!C42="","",ANNEX!C42) | I7: 1 | J7: =FRONT!I31 -> Oral Communication | K7: =FRONT!BI31 | L7: =IF(K7="PASSED","∕","") | M7: {=IFERROR(INDEX(FRONT!I31:BI42,MATCH(1,(FRONT!I31:I42=$M$6)*(FRONT!BI31:BI42=$J$6),0),53),"")}
B8: =IF(FRONT!A35="Core","Core",IF(FRONT!A35="Applied","Applied",IF(FRONT!A35="Specialized","Specialized",IF(FRONT!A35="Other_Subjects","Other_Subjects")))) -> Core | C8: Earth Science | D8: Inquiries, Investigations and Immersion | E8: =IF(ANNEX!C43="","",ANNEX!C43) | J8: =FRONT!I32 -> Komunikasyon at Pananaliksik sa Wika at Kulturang Pilipino | K8: =FRONT!BI32 | L8: =IF(K8="PASSED","∕","") | M8: {=IFERROR(INDEX(FRONT!I58:BI61,MATCH(1,(FRONT!I58:I61=$M$6)*(FRONT!BI58:BI61=$J$6),0),53),"")}
B9: =IF(FRONT!A36="Core","Core",IF(FRONT!A36="Applied","Applied",IF(FRONT!A36="Specialized","Specialized",IF(FRONT!A36="Other_Subjects","Other_Subjects")))) -> Core | C9: General Mathematics | D9: Practical Research 1 | E9: =IF(ANNEX!C44="","",ANNEX!C44) | J9: =FRONT!I33 -> Media and Information Literacy | K9: =FRONT!BI33 | L9: =IF(K9="PASSED","∕","") | M9: {=IFERROR(INDEX(FRONT!I74:BI85,MATCH(1,(FRONT!I74:I85=$M$6)*(FRONT!BI74:BI85=$J$6),0),53),"")}
B10: =IF(FRONT!A37="Core","Core",IF(FRONT!A37="Applied","Applied",IF(FRONT!A37="Specialized","Specialized",IF(FRONT!A37="Other_Subjects","Other_Subjects")))) -> Core | C10: Introduction to the Philosophy of the Human Person/Pambungad sa Pilosopiya ng Tao | D10: Practical Research 2 | E10: =IF(ANNEX!C45="","",ANNEX!C45) | J10: =FRONT!I34 -> General Mathematics | K10: =FRONT!BI34 | L10: =IF(K10="PASSED","∕","") | M10: {=IFERROR(INDEX(FRONT!I101:BI104,MATCH(1,(FRONT!I101:I104=$M$6)*(FRONT!BI101:BI104=$J$6),0),53),"")}
B11: =IF(FRONT!A38="Core","Core",IF(FRONT!A38="Applied","Applied",IF(FRONT!A38="Specialized","Specialized",IF(FRONT!A38="Other_Subjects","Other_Subjects")))) -> Core | C11: Komunikasyon at Pananaliksik sa Wika at Kulturang Pilipino | E11: =IF(ANNEX!C46="","",ANNEX!C46) | J11: =FRONT!I35 -> Earth Science | K11: =FRONT!BI35 | L11: =IF(K11="PASSED","∕","") | M11: {=IFERROR(INDEX(BACK!I11:BI22,MATCH(1,(BACK!I11:I22=$M$6)*(BACK!BI11:BI22=$J$6),0),53),"")}
B12: =IF(FRONT!A39="Core","Core",IF(FRONT!A39="Applied","Applied",IF(FRONT!A39="Specialized","Specialized",IF(FRONT!A39="Other_Subjects","Other_Subjects")))) -> Specialized | C12: Media and Information Literacy | E12: =IF(ANNEX!C47="","",ANNEX!C47) | J12: =FRONT!I36 -> Personal Development/Pansariling Kaunlaran | K12: =FRONT!BI36 | L12: =IF(K12="PASSED","∕","") | M12: {=IFERROR(INDEX(BACK!I38:BI41,MATCH(1,(BACK!I38:I41=$M$6)*(BACK!BI38:BI41=$J$6),0),53),"")}
B13: =IF(FRONT!A40="Core","Core",IF(FRONT!A40="Applied","Applied",IF(FRONT!A40="Specialized","Specialized",IF(FRONT!A40="Other_Subjects","Other_Subjects")))) -> Other_Subjects | C13: Oral Communication | J13: =FRONT!I37 -> Understanding Culture, Society and Politics | K13: =FRONT!BI37 | L13: =IF(K13="PASSED","∕","") | M13: {=IFERROR(INDEX(BACK!I54:BI65,MATCH(1,(BACK!I54:I65=$M$6)*(BACK!BI54:BI65=$J$6),0),53),"")}
B14: =IF(FRONT!A41="Core","Core",IF(FRONT!A41="Applied","Applied",IF(FRONT!A41="Specialized","Specialized",IF(FRONT!A41="Other_Subjects","Other_Subjects")))) -> FALSE | C14: Pagbasa at Pagsusuri ng Iba't Ibang Teksto Tungo sa Pananaliksik | J14: =FRONT!I38 -> Physical Education and Health | K14: =FRONT!BI38 | L14: =IF(K14="PASSED","∕","") | M14: {=IFERROR(INDEX(BACK!I81:BI84,MATCH(1,(BACK!I81:I84=$M$6)*(BACK!BI81:BI84=$J$6),0),53),"")}
B15: =IF(FRONT!A42="Core","Core",IF(FRONT!A42="Applied","Applied",IF(FRONT!A42="Specialized","Specialized",IF(FRONT!A42="Other_Subjects","Other_Subjects")))) -> FALSE | C15: Personal Development/Pansariling Kaunlaran | J15: =FRONT!I39 -> Organization and Management | K15: =FRONT!BI39 | L15: =IF(K15="PASSED","∕","")
A16: 2 | B16: =IF(FRONT!A58="Core","Core",IF(FRONT!A58="Applied","Applied",IF(FRONT!A58="Specialized","Specialized",IF(FRONT!A58="Other_Subjects","Other_Subjects")))) -> FALSE | C16: Physical Education and Health | J16: =FRONT!I40 -> Homeroom Guidance | K16: =FRONT!BI40 | L16: =IF(K16="PASSED","∕","")
B17: =IF(FRONT!A59="Core","Core",IF(FRONT!A59="Applied","Applied",IF(FRONT!A59="Specialized","Specialized",IF(FRONT!A59="Other_Subjects","Other_Subjects")))) -> FALSE | C17: Physical Science* | J17: =FRONT!I41 -> 0 | K17: =FRONT!BI41 | L17: =IF(K17="PASSED","∕","")
B18: =IF(FRONT!#REF!="Core","Core",IF(FRONT!#REF!="Applied","Applied",IF(FRONT!#REF!="Specialized","Specialized",IF(FRONT!#REF!="Other_Subjects","Other_Subjects")))) -> #REF! | C18: Reading and Writing | J18: =FRONT!I42 -> 0 | K18: =FRONT!BI42 | L18: =IF(K18="PASSED","∕","")
B19: =IF(FRONT!#REF!="Core","Core",IF(FRONT!#REF!="Applied","Applied",IF(FRONT!#REF!="Specialized","Specialized",IF(FRONT!#REF!="Other_Subjects","Other_Subjects")))) -> #REF! | C19: Statistics and Probability | I19: 2 | J19: =FRONT!I58 -> 0 | K19: =FRONT!BI58 | L19: =IF(K19="PASSED","∕","")
B20: =IF(FRONT!#REF!="Core","Core",IF(FRONT!#REF!="Applied","Applied",IF(FRONT!#REF!="Specialized","Specialized",IF(FRONT!#REF!="Other_Subjects","Other_Subjects")))) -> #REF! | C20: Understanding Culture, Society and Politics | J20: =FRONT!I59 -> 0 | K20: =FRONT!BI59 | L20: =IF(K20="PASSED","∕","")
B21: =IF(FRONT!#REF!="Core","Core",IF(FRONT!#REF!="Applied","Applied",IF(FRONT!#REF!="Specialized","Specialized",IF(FRONT!#REF!="Other_Subjects","Other_Subjects")))) -> #REF! | C21: =IF(ANNEX!C26="","",ANNEX!C26) | J21: =FRONT!#REF! -> #REF! | K21: =FRONT!#REF! -> #REF! | L21: =IF(K21="PASSED","∕","") -> #REF!
B22: =IF(FRONT!A60="Core","Core",IF(FRONT!A60="Applied","Applied",IF(FRONT!A60="Specialized","Specialized",IF(FRONT!A60="Other_Subjects","Other_Subjects")))) -> FALSE | C22: =IF(ANNEX!C27="","",ANNEX!C27) | J22: =FRONT!#REF! -> #REF! | K22: =FRONT!#REF! -> #REF! | L22: =IF(K22="PASSED","∕","") -> #REF!
B23: =IF(FRONT!A61="Core","Core",IF(FRONT!A61="Applied","Applied",IF(FRONT!A61="Specialized","Specialized",IF(FRONT!A61="Other_Subjects","Other_Subjects")))) -> FALSE | J23: =FRONT!#REF! -> #REF! | K23: =FRONT!#REF! -> #REF! | L23: =IF(K23="PASSED","∕","") -> #REF!
B24: =IF(FRONT!A62="Core","Core",IF(FRONT!A62="Applied","Applied",IF(FRONT!A62="Specialized","Specialized",IF(FRONT!A62="Other_Subjects","Other_Subjects")))) -> FALSE | J24: =FRONT!#REF! -> #REF! | K24: =FRONT!#REF! -> #REF! | L24: =IF(K24="PASSED","∕","") -> #REF!
B25: =IF(FRONT!A63="Core","Core",IF(FRONT!A63="Applied","Applied",IF(FRONT!A63="Specialized","Specialized",IF(FRONT!A63="Other_Subjects","Other_Subjects")))) -> FALSE | J25: =FRONT!I60 -> 0 | K25: =FRONT!BI60 | L25: =IF(K25="PASSED","∕","")
B26: =IF(FRONT!A64="Core","Core",IF(FRONT!A64="Applied","Applied",IF(FRONT!A64="Specialized","Specialized",IF(FRONT!A64="Other_Subjects","Other_Subjects")))) -> FALSE | J26: =FRONT!I61 -> 0 | K26: =FRONT!BI61 | L26: =IF(K26="PASSED","∕","")
B27: =IF(FRONT!A65="Core","Core",IF(FRONT!A65="Applied","Applied",IF(FRONT!A65="Specialized","Specialized",IF(FRONT!A65="Other_Subjects","Other_Subjects")))) -> FALSE | I27: 3 | J27: =FRONT!I74 -> Reading and Writing | K27: =FRONT!BI74 | L27: =IF(K27="PASSED","∕","")
A28: 3 | B28: =IF(FRONT!A74="Core","Core",IF(FRONT!A74="Applied","Applied",IF(FRONT!A74="Specialized","Specialized",IF(FRONT!A74="Other_Subjects","Other_Subjects")))) -> Core | J28: =FRONT!I75 -> Pagbasa at Pagsusuri ng Iba't Ibang Teksto Tungo sa Pananaliksik | K28: =FRONT!BI75 | L28: =IF(K28="PASSED","∕","")
B29: =IF(FRONT!A75="Core","Core",IF(FRONT!A75="Applied","Applied",IF(FRONT!A75="Specialized","Specialized",IF(FRONT!A75="Other_Subjects","Other_Subjects")))) -> Core | J29: =FRONT!I76 -> 21st Century Literature from the Philippines and the World | K29: =FRONT!BI76 | L29: =IF(K29="PASSED","∕","")
B30: =IF(FRONT!A76="Core","Core",IF(FRONT!A76="Applied","Applied",IF(FRONT!A76="Specialized","Specialized",IF(FRONT!A76="Other_Subjects","Other_Subjects")))) -> Core | J30: =FRONT!I77 -> Contemporary Philippine Arts from the Regions | K30: =FRONT!BI77 | L30: =IF(K30="PASSED","∕","")
B31: =IF(FRONT!A77="Core","Core",IF(FRONT!A77="Applied","Applied",IF(FRONT!A77="Specialized","Specialized",IF(FRONT!A77="Other_Subjects","Other_Subjects")))) -> Core | J31: =FRONT!I78 -> Statistics and Probability | K31: =FRONT!BI78 | L31: =IF(K31="PASSED","∕","")
B32: =IF(FRONT!A78="Core","Core",IF(FRONT!A78="Applied","Applied",IF(FRONT!A78="Specialized","Specialized",IF(FRONT!A78="Other_Subjects","Other_Subjects")))) -> Core | J32: =FRONT!I79 -> Physical Science* | K32: =FRONT!BI79 | L32: =IF(K32="PASSED","∕","")
B33: =IF(FRONT!A79="Core","Core",IF(FRONT!A79="Applied","Applied",IF(FRONT!A79="Specialized","Specialized",IF(FRONT!A79="Other_Subjects","Other_Subjects")))) -> Core | J33: =FRONT!I80 -> Introduction to the Philosophy of the Human Person/Pambungad sa Pilosopiya ng Tao | K33: =FRONT!BI80 | L33: =IF(K33="PASSED","∕","")
B34: =IF(FRONT!A80="Core","Core",IF(FRONT!A80="Applied","Applied",IF(FRONT!A80="Specialized","Specialized",IF(FRONT!A80="Other_Subjects","Other_Subjects")))) -> Core | J34: =FRONT!I81 -> Physical Education and Health | K34: =FRONT!BI81 | L34: =IF(K34="PASSED","∕","")
B35: =IF(FRONT!A81="Core","Core",IF(FRONT!A81="Applied","Applied",IF(FRONT!A81="Specialized","Specialized",IF(FRONT!A81="Other_Subjects","Other_Subjects")))) -> Core | J35: =FRONT!I82 -> Trend, Networks, and Critical Thinking in the 21st Century | K35: =FRONT!BI82 | L35: =IF(K35="PASSED","∕","")
B36: =IF(FRONT!A82="Core","Core",IF(FRONT!A82="Applied","Applied",IF(FRONT!A82="Specialized","Specialized",IF(FRONT!A82="Other_Subjects","Other_Subjects")))) -> Specialized | J36: =FRONT!I83 -> Homeroom Guidance | K36: =FRONT!BI83 | L36: =IF(K36="PASSED","∕","")
B37: =IF(FRONT!A83="Core","Core",IF(FRONT!A83="Applied","Applied",IF(FRONT!A83="Specialized","Specialized",IF(FRONT!A83="Other_Subjects","Other_Subjects")))) -> Other_Subjects | J37: =FRONT!I84 -> 0 | K37: =FRONT!BI84 | L37: =IF(K37="PASSED","∕","")
B38: =IF(FRONT!A84="Core","Core",IF(FRONT!A84="Applied","Applied",IF(FRONT!A84="Specialized","Specialized",IF(FRONT!A84="Other_Subjects","Other_Subjects")))) -> FALSE | J38: =FRONT!I85 -> 0 | K38: =FRONT!BI85 | L38: =IF(K38="PASSED","∕","")
B39: =IF(FRONT!A85="Core","Core",IF(FRONT!A85="Applied","Applied",IF(FRONT!A85="Specialized","Specialized",IF(FRONT!A85="Other_Subjects","Other_Subjects")))) -> FALSE | I39: 4 | J39: =FRONT!I101 -> 0 | K39: =FRONT!BI101 | L39: =IF(K39="PASSED","∕","")
A40: 4 | B40: =IF(FRONT!A101="Core","Core",IF(FRONT!A101="Applied","Applied",IF(FRONT!A101="Specialized","Specialized",IF(FRONT!A101="Other_Subjects","Other_Subjects")))) -> FALSE | J40: =FRONT!I102 -> 0 | K40: =FRONT!BI102 | L40: =IF(K40="PASSED","∕","")
...
